Workbook

Sheet README
A1: DEMO Financial Statement Dataset — Horizon Financial Services Ltd. (Fictional NBFC)
A2: Purpose | B2: Second synthetic dataset — a different entity TYPE from the bank dataset, so you can test whether your extraction/validation pipeline generalises across formats, not just across numbers.
A3: Format basis | B3: Modelled on Division III of Schedule III to the Companies Act, 2013 — the statutory format for Non-Banking Financial Companies (NBFCs) that follow Ind AS. Unlike a bank's Form A/B, an NBFC balance sheet is split into Financial Assets/Liabilities and Non-Financial Assets/Liabilities.
A4: Currency / Units | B4: All figures in Rupees Lakhs (Rs. Lakhs) unless stated otherwise.
A5: Years | B5: Current Year = FY 2025-26 (year ended 31 March 2026). Previous Year = FY 2024-25.
A6: Tabs | B6: Balance Sheet | Statement of Profit and Loss | Cash Flow | Notes | (this) README
A7: Notable real detail | B7: Statutory Reserve in Note 21 is built using the real rule under Section 45-IC of the RBI Act, 1934: every NBFC must transfer at least 20% of net profit to a reserve fund every year before declaring dividend. That transfer is a live formula (=20% of the Net Profit computed on the P&L tab), so if you corrupt Net Profit later, this cell will visibly drift too — useful for a consistency-check demo.
A8: Color legend | B8: Blue = hardcoded input. Black = formula (sums/checks). Green = link to another sheet.
A9: Status | B9: DEMO / GENERIC dataset — not an official Cognizant, MCA or RBI template. Hackathon MVP use only.

Sheet Profit and Loss
A1: Horizon Financial Services Ltd. — Statement of Profit and Loss for the year ended 31 March 2026
A2: (Rs. in Lakhs)
A3: Particulars | B3: Note | C3: Current Year (FY26) | D3: Previous Year (FY25)
A4: I. Revenue from Operations
A5: Interest Income | C5: 22000 | D5: 19500
A6: Fee and Commission Income | C6: 1800 | D6: 1600
A7: Net Gain on Fair Value Changes | C7: 500 | D7: 400
A8: Total Revenue from Operations (I) | C8: =SUM(C5:C7) | D8: =SUM(D5:D7)
A10: II. Other Income
A11: Other Income | C11: 300 | D11: 250
A13: Total Income (I + II) | C13: =C8+C11 | D13: =D8+D11
A15: III. Expenses
A16: Finance Costs | C16: 11200 | D16: 9800
A17: Impairment on Financial Instruments | C17: 2400 | D17: 2100
A18: Employee Benefits Expenses | C18: 2800 | D18: 2500
A19: Depreciation and Amortisation | C19: 600 | D19: 550
A20: Other Expenses | C20: 1600 | D20: 1400
A21: Total Expenses (III) | C21: =SUM(C16:C20) | D21: =SUM(D16:D20)
A23: IV. Profit Before Tax (Total Income - Total Expenses) | C23: =C13-C21 | D23: =D13-D21
A24: Tax Expense (Current and Deferred) | C24: 900 | D24: 850
A25: V. Profit for the Year (IV - Tax Expense) | C25: =C23-C24 | D25: =D23-D24

Sheet Notes
A1: Horizon Financial Services Ltd. — Notes Forming Part of the Balance Sheet as at 31 March 2026
A2: (Rs. in Lakhs)
A3: Particulars | B3: Current Year (FY26) | C3: Previous Year (FY25)
A4: Note 3 - Cash and Cash Equivalents
A5: Cash on Hand | B5: 200 | C5: 180
A6: Balances with Banks | B6: 3000 | C6: 2620
A7: Total (Note 3) | B7: =SUM(B5:B6) | C7: =SUM(C5:C6)
A9: Note 4 - Bank Balances other than Cash and Cash Equivalents
A10: Fixed Deposits with Banks | B10: 1500 | C10: 1200
A11: Total (Note 4) | B11: =SUM(B10:B10) | C11: =SUM(C10:C10)
A13: Note 5 - Loans
A14: Term Loans | B14: 98000 | C14: 86000
A15: Working Capital Loans | B15: 47000 | C15: 42000
A16: Total (Note 5) | B16: =SUM(B14:B15) | C16: =SUM(C14:C15)
A18: Note 6 - Investments
A19: Government Securities | B19: 8000 | C19: 7000
A20: Mutual Funds | B20: 4500 | C20: 3800
A21: Total (Note 6) | B21: =SUM(B19:B20) | C21: =SUM(C19:C20)
A23: Note 7 - Other Financial Assets
A24: Security Deposits | B24: 900 | C24: 800
A25: Interest Accrued but not Due | B25: 1400 | C25: 1200
A26: Total (Note 7) | B26: =SUM(B24:B25) | C26: =SUM(C24:C25)
A28: Note 8 - Property, Plant and Equipment
A29: Office Premises | B29: 2600 | C29: 2400
A30: Furniture, Fixtures and Vehicles | B30: 1200 | C30: 1100
A31: Total (Note 8) | B31: =SUM(B29:B30) | C31: =SUM(C29:C30)
A33: Note 9 - Intangible Assets
A34: Computer Software | B34: 600 | C34: 550
A35: Total (Note 9) | B35: =SUM(B34:B34) | C35: =SUM(C34:C34)
A37: Note 10 - Deferred Tax Assets (net)
A38: Deferred Tax Assets (net) | B38: 900 | C38: 850
A39: Total (Note 10) | B39: =SUM(B38:B38) | C39: =SUM(C38:C38)
A41: Note 11 - Other Non-Financial Assets
A42: Prepaid Expenses | B42: 500 | C42: 450
A43: Advances to Vendors | B43: 700 | C43: 650
A44: Total (Note 11) | B44: =SUM(B42:B43) | C44: =SUM(C42:C43)
A46: Note 12 - Trade Payables
A47: Trade Payables | B47: 800 | C47: 700
A48: Total (Note 12) | B48: =SUM(B47:B47) | C48: =SUM(C47:C47)
A50: Note 13 - Debt Securities
...

Sheet Balance Sheet
A1: Horizon Financial Services Ltd. — Balance Sheet as at 31 March 2026 (Ind AS, Schedule III Division III)
A2: (Rs. in Lakhs)
A3: Particulars | B3: Note | C3: Current Year (FY26) | D3: Previous Year (FY25)
A4: ASSETS
A5: Financial Assets
A6: Cash and Cash Equivalents | B6: 3 | C6: =Notes!B7 | D6: =Notes!C7
A7: Bank Balances other than Cash and Cash Equivalents | B7: 4 | C7: =Notes!B11 | D7: =Notes!C11
A8: Loans | B8: 5 | C8: =Notes!B16 | D8: =Notes!C16
A9: Investments | B9: 6 | C9: =Notes!B21 | D9: =Notes!C21
A10: Other Financial Assets | B10: 7 | C10: =Notes!B26 | D10: =Notes!C26
A11: Total Financial Assets | C11: =SUM(C6:C10) | D11: =SUM(D6:D10)
A12: Non-Financial Assets
A13: Property, Plant and Equipment | B13: 8 | C13: =Notes!B31 | D13: =Notes!C31
A14: Intangible Assets | B14: 9 | C14: =Notes!B35 | D14: =Notes!C35
A15: Deferred Tax Assets (net) | B15: 10 | C15: =Notes!B39 | D15: =Notes!C39
A16: Other Non-Financial Assets | B16: 11 | C16: =Notes!B44 | D16: =Notes!C44
A17: Total Non-Financial Assets | C17: =SUM(C13:C16) | D17: =SUM(D13:D16)
A18: TOTAL ASSETS | C18: =C11+C17 | D18: =D11+D17
A20: LIABILITIES
A21: Financial Liabilities
A22: Trade Payables | B22: 12 | C22: =Notes!B48 | D22: =Notes!C48
A23: Debt Securities | B23: 13 | C23: =Notes!B53 | D23: =Notes!C53
A24: Borrowings (Other than Debt Securities) | B24: 14 | C24: =Notes!B58 | D24: =Notes!C58
A25: Subordinated Liabilities | B25: 15 | C25: =Notes!B62 | D25: =Notes!C62
A26: Other Financial Liabilities | B26: 16 | C26: =Notes!B67 | D26: =Notes!C67
A27: Total Financial Liabilities | C27: =SUM(C22:C26) | D27: =SUM(D22:D26)
A28: Non-Financial Liabilities
A29: Current Tax Liabilities (net) | B29: 17 | C29: =Notes!B71 | D29: =Notes!C71
A30: Provisions | B30: 18 | C30: =Notes!B76 | D30: =Notes!C76
A31: Other Non-Financial Liabilities | B31: 19 | C31: =Notes!B80 | D31: =Notes!C80
A32: Total Non-Financial Liabilities | C32: =SUM(C29:C31) | D32: =SUM(D29:D31)
A33: Total Liabilities | C33: =C27+C32 | D33: =D27+D32
A35: EQUITY
A36: Equity Share Capital | B36: 20 | C36: =Notes!B84 | D36: =Notes!C84
A37: Other Equity | B37: 21 | C37: =Notes!B91 | D37: =Notes!C91
A38: Total Equity | C38: =SUM(C36:C37) | D38: =SUM(D36:D37)
A39: TOTAL LIABILITIES AND EQUITY | C39: =C33+C38 | D39: =D33+D38
A41: Tie-out check: Total Assets minus Total Liabilities and Equity (must be 0) | C41: =C18-C39 | D41: =D18-D39

Sheet Cash Flow
A1: Horizon Financial Services Ltd. — Cash Flow Statement for the year ended 31 March 2026 (Indirect Method, Ind AS 7)
A2: (Rs. in Lakhs) — Current Year only. Previous Year's cash flow would need FY 2023-24 closing balances, which fall outside this 2-year dataset.
A3: Particulars | B3: Current Year (FY26)
A4: A. Cash Flow from Operating Activities
A5: Profit for the Year | B5: ='Profit and Loss'!$C$25
A6: Adjustments for changes in operating assets and liabilities:
A7: (Increase) in Loans | B7: =-(Notes!B16-Notes!C16)
A8: (Increase) in Investments | B8: =-(Notes!B21-Notes!C21)
A9: (Increase) in Other Financial Assets | B9: =-(Notes!B26-Notes!C26)
A10: (Increase) in Bank Balances other than Cash and Cash Equivalents | B10: =-(Notes!B11-Notes!C11)
A11: (Increase) in Other Non-Financial Assets | B11: =-(Notes!B44-Notes!C44)
A12: (Increase) in Deferred Tax Assets (net) | B12: =-(Notes!B39-Notes!C39)
A13: Increase in Trade Payables | B13: =Notes!B48-Notes!C48
A14: Increase in Other Financial Liabilities | B14: =Notes!B67-Notes!C67
A15: Increase in Current Tax Liabilities | B15: =Notes!B71-Notes!C71
A16: Increase in Provisions | B16: =Notes!B76-Notes!C76
A17: Increase in Other Non-Financial Liabilities | B17: =Notes!B80-Notes!C80
A18: Net Cash Generated from / (Used in) Operating Activities | B18: =SUM(B5:B17)
A20: B. Cash Flow from Investing Activities
A21: (Purchase of Property, Plant and Equipment) | B21: =-(Notes!B31-Notes!C31)
A22: (Purchase of Intangible Assets) | B22: =-(Notes!B35-Notes!C35)
A23: Net Cash Used in Investing Activities | B23: =SUM(B21:B22)
A25: C. Cash Flow from Financing Activities
A26: Increase in Debt Securities | B26: =Notes!B53-Notes!C53
A27: Increase in Borrowings (Other than Debt Securities) | B27: =Notes!B58-Notes!C58
A28: Increase in Subordinated Liabilities | B28: =Notes!B62-Notes!C62
A29: Net Cash from Financing Activities | B29: =SUM(B26:B28)
A31: Net Increase / (Decrease) in Cash and Cash Equivalents (A + B + C) | B31: =B18+B23+B29
A32: Cash and Cash Equivalents at the Beginning of the Year (Note 3, PY) | B32: =Notes!C7
A33: Cash and Cash Equivalents at the End of the Year (Note 3, CY) | B33: =Notes!B7
A34: Tie-out check: Opening + Net Increase - Closing (must be 0) | B34: =B32+B31-B33
