Workbook

Sheet README
A1: DEMO Financial Statement Dataset — Sunrise National Bank Ltd. (Fictional)
A2: Purpose | B2: Synthetic, internally-consistent bank financial statements for building/testing a financial statement review tool. NOT a real bank. All figures are invented.
A3: Format basis | B3: Modelled on Form A (Balance Sheet) and Form B (Profit & Loss Account) of the Third Schedule to the Banking Regulation Act, 1949 (Section 29) — the real statutory layout Indian banks use. Simplified: only the schedules relevant to this project are included (1-11), not all 18.
A4: Currency / Units | B4: All figures in Rupees Lakhs (₹ Lakhs) unless stated otherwise.
A5: Years | B5: Current Year = FY 2025-26 (year ended 31 March 2026). Previous Year = FY 2024-25.
A6: Tabs | B6: Balance Sheet | Profit and Loss | Schedules | Notes (Schedule 18)
A7: How it's wired | B7: Balance Sheet and P&L Reserves line pull their numbers FROM the Schedules tab via formulas (green text = cross-sheet link). This means the file is consistent BY CONSTRUCTION right now. To create a broken test file, you deliberately overwrite one linked/derived cell with a hardcoded wrong number — that's how you'll generate the corrupted variants for your detection engine.
A8: Color legend | B8: Blue = hardcoded input. Black = formula (sums/checks). Green = link to another sheet.
A9: Status | B9: DEMO / GENERIC dataset — not an official Cognizant or RBI template. Built for hackathon MVP use only.

Sheet Profit and Loss
A1: Sunrise National Bank Ltd. — Profit and Loss Account for the year ended 31 March 2026 (Form B)
A2: (₹ in Lakhs)
A3: Particulars | B3: Sch. | C3: Current Year (FY26) | D3: Previous Year (FY25)
A4: I. INCOME
A5: Interest Earned | C5: 21500 | D5: 19200
A6: Other Income | C6: 2300 | D6: 2050
A7: Total Income (I) | C7: =SUM(C5:C6) -> 23800 | D7: =SUM(D5:D6) -> 21250
A9: II. EXPENDITURE
A10: Interest Expended | C10: 12800 | D10: 11500
A11: Operating Expenses | C11: 6200 | D11: 5600
A12: Provisions and Contingencies | C12: 2650 | D12: 2300
A13: Total Expenditure (II) | C13: =SUM(C10:C12) -> 21650 | D13: =SUM(D10:D12) -> 19400
A15: III. PROFIT / LOSS
A16: Net Profit for the year (I - II) | C16: =C7-C13 -> 2150 | D16: =D7-D13 -> 1850

Sheet Schedules
A1: Sunrise National Bank Ltd. — Schedules forming part of the Balance Sheet as at 31 March 2026
A2: (₹ in Lakhs)
A3: Particulars | B3: Current Year (FY26) | C3: Previous Year (FY25)
A4: Schedule 1 - Capital
A5: Issued, Subscribed and Paid-up Capital | B5: 12000 | C5: 12000
A6: Total (Schedule 1) | B6: =SUM(B5:B5) -> 12000 | C6: =SUM(C5:C5) -> 12000
A8: Schedule 2 - Reserves and Surplus
A9: I. Statutory Reserves | B9: 8500 | C9: 7200
A10: II. Capital Reserves | B10: 1200 | C10: 1200
A11: III. Share Premium | B11: 3000 | C11: 3000
A12: IV. Revenue and Other Reserves | B12: 4300 | C12: 3800
A13: V. Balance in Profit and Loss Account | B13: ='Profit and Loss'!$C$16 -> 2150 | C13: ='Profit and Loss'!$D$16 -> 1850
A14: Total (Schedule 2) | B14: =SUM(B9:B13) -> 19150 | C14: =SUM(C9:C13) -> 17050
A16: Schedule 3 - Deposits
A17: Demand Deposits | B17: 15000 | C17: 13500
A18: Savings Bank Deposits | B18: 42000 | C18: 38000
A19: Term Deposits | B19: 98000 | C19: 90000
A20: Total (Schedule 3) | B20: =SUM(B17:B19) -> 155000 | C20: =SUM(C17:C19) -> 141500
A22: Schedule 4 - Borrowings
A23: Borrowings in India | B23: 18000 | C23: 16000
A24: Borrowings outside India | B24: 4000 | C24: 3500
A25: Total (Schedule 4) | B25: =SUM(B23:B24) -> 22000 | C25: =SUM(C23:C24) -> 19500
A27: Schedule 5 - Other Liabilities and Provisions
A28: Bills Payable | B28: 2100 | C28: 1900
A29: Inter-office Adjustments | B29: 500 | C29: 450
A30: Interest Accrued | B30: 800 | C30: 700
A31: Others (including Provisions) | B31: 3600 | C31: 3200
A32: Total (Schedule 5) | B32: =SUM(B28:B31) -> 7000 | C32: =SUM(C28:C31) -> 6250
A34: Schedule 6 - Cash and Balances with Reserve Bank of India
A35: Cash in Hand | B35: 1200 | C35: 1050
A36: Balances with Reserve Bank of India | B36: 9800 | C36: 8950
A37: Total (Schedule 6) | B37: =SUM(B35:B36) -> 11000 | C37: =SUM(C35:C36) -> 10000
A39: Schedule 7 - Balances with Banks and Money at Call and Short Notice
A40: Balances with Banks and Money at Call | B40: 6500 | C40: 5800
A41: Total (Schedule 7) | B41: =SUM(B40:B40) -> 6500 | C41: =SUM(C40:C40) -> 5800
A43: Schedule 8 - Investments
A44: Government Securities | B44: 48000 | C44: 44000
A45: Other Investments | B45: 9000 | C45: 8200
A46: Total (Schedule 8) | B46: =SUM(B44:B45) -> 57000 | C46: =SUM(C44:C45) -> 52200
A48: Schedule 9 - Advances
...

Sheet Balance Sheet
A1: Sunrise National Bank Ltd. — Balance Sheet as at 31 March 2026 (Form A)
A2: (₹ in Lakhs)
A3: Particulars | B3: Sch. | C3: Current Year (FY26) | D3: Previous Year (FY25)
A4: CAPITAL AND LIABILITIES
A5: Capital | B5: 1 | C5: =Schedules!B6 -> 12000 | D5: =Schedules!C6 -> 12000
A6: Reserves and Surplus | B6: 2 | C6: =Schedules!B14 -> 19150 | D6: =Schedules!C14 -> 17050
A7: Deposits | B7: 3 | C7: =Schedules!B20 -> 155000 | D7: =Schedules!C20 -> 141500
A8: Borrowings | B8: 4 | C8: =Schedules!B25 -> 22000 | D8: =Schedules!C25 -> 19500
A9: Other Liabilities and Provisions | B9: 5 | C9: =Schedules!B32 -> 7000 | D9: =Schedules!C32 -> 6250
A10: TOTAL LIABILITIES | C10: =SUM(C5:C9) -> 215150 | D10: =SUM(D5:D9) -> 196300
A12: ASSETS
A13: Cash and Balances with Reserve Bank of India | B13: 6 | C13: =Schedules!B37 -> 11000 | D13: =Schedules!C37 -> 10000
A14: Balances with Banks and Money at Call and Short Notice | B14: 7 | C14: =Schedules!B41 -> 6500 | D14: =Schedules!C41 -> 5800
A15: Investments | B15: 8 | C15: =Schedules!B46 -> 57000 | D15: =Schedules!C46 -> 52200
A16: Advances | B16: 9 | C16: =Schedules!B51 -> 130000 | D16: =Schedules!C51 -> 118000
A17: Fixed Assets | B17: 10 | C17: =Schedules!B55 -> 4650 | D17: =Schedules!C55 -> 4300
A18: Other Assets | B18: 11 | C18: =Schedules!B59 -> 6000 | D18: =Schedules!C59 -> 6000
A19: TOTAL ASSETS | C19: =SUM(C13:C18) -> 215150 | D19: =SUM(D13:D18) -> 196300
A21: Tie-out check: Total Assets minus Total Liabilities (must be 0) | C21: =C19-C10 -> 0 | D21: =D19-D10 -> 0

Sheet Notes (Schedule 18)
A1: Sunrise National Bank Ltd. — Notes Forming Part of the Financial Statements (Schedule 18-style)
A3: 1 | B3: Basis of Preparation: The financial statements have been prepared under the historical cost convention and in accordance with the Third Schedule of the Banking Regulation Act, 1949, and applicable RBI guidelines.
A5: 2 | B5: Cash and Balances with Reserve Bank of India: Cash and balances with the Reserve Bank of India as at the end of the year amounted to Rs. 11,000 lakhs (Previous Year: Rs. 10,000 lakhs), as detailed in Schedule 6.
A7: 3 | B7: Advances: Gross Advances stood at Rs. 130,000 lakhs as at 31 March 2026 (Previous Year: Rs. 118,000 lakhs), as detailed in Schedule 9.
A9: 4 | B9: Profit for the Year: Net Profit for the year under review was Rs. 2,150 lakhs, as against Rs. 1,850 lakhs in the previous year, an increase of approximately 16.2 percent, mainly attributable to growth in interest income on advances.
A11: 5 | B11: Deposits: Total Deposits grew to Rs. 155,000 lakhs from Rs. 141,500 lakhs in the previous year, an increase of approximately 9.5 percent, driven primarily by growth in term deposits.

Sheet Cash Flow
A1: Sunrise National Bank Ltd. — Cash Flow Statement for the year ended 31 March 2026 (Indirect Method)
A2: (Rs. in Lakhs) — Current Year only. Previous Year's cash flow would need FY 2023-24 closing balances, which fall outside this 2-year dataset.
A3: Particulars | B3: Current Year (FY26)
A4: A. Cash Flow from Operating Activities
A5: Increase in Deposits | B5: =Schedules!B20-Schedules!C20 -> 13500
A6: Increase in Other Liabilities and Provisions | B6: =Schedules!B32-Schedules!C32 -> 750
A7: Increase in Reserves and Surplus (net) | B7: =Schedules!B14-Schedules!C14 -> 2100
A8: (Increase) in Investments | B8: =-(Schedules!B46-Schedules!C46) -> -4800
A9: (Increase) in Advances | B9: =-(Schedules!B51-Schedules!C51) -> -12000
A10: (Increase) in Other Assets | B10: =-(Schedules!B59-Schedules!C59) -> 0
A11: Net Cash Generated from / (Used in) Operating Activities | B11: =SUM(B5:B10) -> -450
A13: B. Cash Flow from Investing Activities
A14: (Purchase of Fixed Assets) | B14: =-(Schedules!B55-Schedules!C55) -> -350
A15: Net Cash Used in Investing Activities | B15: =B14 -> -350
A17: C. Cash Flow from Financing Activities
A18: Increase in Capital | B18: =Schedules!B6-Schedules!C6 -> 0
A19: Increase in Borrowings | B19: =Schedules!B25-Schedules!C25 -> 2500
A20: Net Cash from Financing Activities | B20: =SUM(B18:B19) -> 2500
A22: Net Increase / (Decrease) in Cash and Cash Equivalents (A + B + C) | B22: =B11+B15+B20 -> 1700
A23: Cash and Cash Equivalents at the Beginning of the Year (Sch. 6 + Sch. 7, PY) | B23: =Schedules!C37+Schedules!C41 -> 15800
A24: Cash and Cash Equivalents at the End of the Year (Sch. 6 + Sch. 7, CY) | B24: =Schedules!B37+Schedules!B41 -> 17500
A25: Tie-out check: Opening + Net Increase - Closing (must be 0) | B25: =B23+B22-B24 -> 0
